{
	"id": "oval:org.debian:def:314165034998141024561234326817901733564",
	"class": "vulnerability",
	"metadata": {
		"title": "CVE-2019-11324 python-urllib3",
		"affected": {
			"family": "unix",
			"platform": "Debian GNU/Linux 11",
			"product": "python-urllib3"
		},
		"reference": [
			{
				"source": "CVE",
				"ref_id": "CVE-2019-11324",
				"ref_url": "https://cve.mitre.org/cgi-bin/cvename.cgi?name=CVE-2019-11324"
			}
		],
		"description": "The urllib3 library before 1.24.2 for Python mishandles certain cases where the desired set of CA certificates is different from the OS store of CA certificates, which results in SSL connections succeeding in situations where a verification failure is the correct outcome. This is related to use of the ssl_context, ca_certs, or ca_certs_dir argument.",
		"debian": {}
	},
	"criteria": {
		"operator": "AND",
		"criterias": [
			{
				"operator": "OR",
				"criterias": [
					{
						"operator": "AND",
						"criterions": [
							{
								"test_ref": "oval:org.debian.oval:tst:2",
								"comment": "all architecture"
							},
							{
								"test_ref": "oval:org.debian.oval:tst:15768",
								"comment": "python-urllib3 DPKG is earlier than 1.25.6-4"
							}
						]
					}
				]
			}
		],
		"criterions": [
			{
				"test_ref": "oval:org.debian.oval:tst:1",
				"comment": "Debian 11 is installed"
			}
		]
	}
}
