{
	"id": "oval:org.debian:def:293061400995834922108744173112872543416",
	"class": "patch",
	"metadata": {
		"title": "DSA-4161-1 python-django",
		"affected": {
			"family": "unix",
			"platform": "Debian GNU/Linux 9",
			"product": "python-django"
		},
		"reference": [
			{
				"source": "CVE",
				"ref_id": "CVE-2018-7536",
				"ref_url": "https://cve.mitre.org/cgi-bin/cvename.cgi?name=CVE-2018-7536"
			},
			{
				"source": "CVE",
				"ref_id": "CVE-2018-7537",
				"ref_url": "https://cve.mitre.org/cgi-bin/cvename.cgi?name=CVE-2018-7537"
			}
		],
		"description": "security update",
		"debian": {
			"moreinfo": "\nJames Davis discovered two issues in Django, a high-level Python web development framework, that can lead to a denial-of-service attack. An attacker with control on the input of the django.utils.html.urlize() function or django.utils.text.Truncator's chars() and words() methods could craft a string that might stuck the execution of the application.",
			"dsa": "DSA-4161",
			"date": "2018-04-01"
		}
	},
	"criteria": {
		"operator": "AND",
		"criterias": [
			{
				"operator": "OR",
				"criterias": [
					{
						"operator": "AND",
						"criterions": [
							{
								"test_ref": "oval:org.debian.oval:tst:2",
								"comment": "all architecture"
							},
							{
								"test_ref": "oval:org.debian.oval:tst:2769",
								"comment": "python-django DPKG is earlier than 1:1.10.7-2+deb9u1"
							}
						]
					}
				]
			}
		],
		"criterions": [
			{
				"test_ref": "oval:org.debian.oval:tst:1",
				"comment": "Debian 9 is installed"
			}
		]
	}
}
